tox reveals py36 fails the so and tm "creates file tests", 37 and 38 pass.
BUT testing actual installs in a venv shows that all fail to repair themselves. Therefore problem with how importlib.resources was implemented?
And problem with tests?
3.7:
Traceback (most recent call last):
  File "<stdin>", line 1, in <module>
  File "/Users/geoffreysametz/Documents/3.7/venv/lib/python3.7/site-packages/nmrsim/qm.py", line 337, in _tm_cache
    with path_context as p:
  File "/Users/geoffreysametz/.pyenv/versions/3.7.6/lib/python3.7/contextlib.py", line 112, in __enter__
    return next(self.gen)
  File "/Users/geoffreysametz/.pyenv/versions/3.7.6/lib/python3.7/importlib/resources.py", line 201, in path
    with open_binary(package, resource) as fp:
  File "/Users/geoffreysametz/.pyenv/versions/3.7.6/lib/python3.7/importlib/resources.py", line 91, in open_binary
    return reader.open_resource(resource)
  File "<frozen importlib._bootstrap_external>", line 929, in open_resource
FileNotFoundError: [Errno 2] No such file or directory: '/Users/geoffreysametz/Documents/3.7/venv/lib/python3.7/site-packages/nmrsim/bin/T3.npz'

3.6:
Traceback (most recent call last):
  File "/Users/geoffreysametz/Documents/3.6/venv/lib/python3.6/site-packages/importlib_resources/_py3.py", line 85, in open_binary
    return open(full_path, mode='rb')
FileNotFoundError: [Errno 2] No such file or directory: '/Users/geoffreysametz/Documents/3.6/venv/lib/python3.6/site-packages/nmrsim/bin/T3.npz'

During handling of the above exception, another exception occurred:

Traceback (most recent call last):
  File "<stdin>", line 1, in <module>
  File "/Users/geoffreysametz/Documents/3.6/venv/lib/python3.6/site-packages/nmrsim/qm.py", line 337, in _tm_cache
    with path_context as p:
  File "/Users/geoffreysametz/.pyenv/versions/3.6.10/lib/python3.6/contextlib.py", line 81, in __enter__
    return next(self.gen)
  File "/Users/geoffreysametz/Documents/3.6/venv/lib/python3.6/site-packages/importlib_resources/_py3.py", line 188, in path
    with open_binary(package, resource) as fp:
  File "/Users/geoffreysametz/Documents/3.6/venv/lib/python3.6/site-packages/importlib_resources/_py3.py", line 99, in open_binary
    raise FileNotFoundError(message)
FileNotFoundError: 'T3.npz' resource not found in 'nmrsim.bin'
